<?xml version="1.0"?>  
<robot name="Xcar">  
  <link name="base_link">  
    <visual>  
      <geometry>  
        <box size="0.5 .32 .13"/>
    </geometry>  
    <origin rpy="0 0 0" xyz="0.12 0 -0.05"/>   <!-- 1.57075 -->
    <material name="blue">
        <color rgba="0 0 .8 1"/> 
    </material>  
    </visual>  
 </link>  
  
 <link name="right_front_wheel">  
    <visual>  
      <geometry>  
        <cylinder length=".02" radius="0.1"/>
      </geometry>  
      <material name="black">  
        <color rgba="0 0 0 1"/>  
      </material>  
    </visual>  
  </link>  
  
  <joint name="right_front_wheel_joint" type="continuous">  
    <axis xyz="0 0 1"/>  
    <parent link="base_link"/>  
    <child link="right_front_wheel"/>  
    <origin rpy="0 1.57075 1.57075" xyz="0.25 0.16 -0.05"/>
    <limit effort="100" velocity="100"/>  
    <joint_properties damping="0.0" friction="0.0"/>  
  </joint>  
  
  <link name="right_back_wheel">  
    <visual>  
      <geometry>  
        <cylinder length=".02" radius="0.055"/>
      </geometry>  
      <material name="black">  
        <color rgba="0 0 0 1"/>  
      </material>  
    </visual>  
  </link>  
  
  <joint name="right_back_wheel_joint" type="continuous">  
    <axis xyz="0 0 1"/>  
    <parent link="base_link"/>  
    <child link="right_back_wheel"/>  
    <origin rpy="0 1.57075 1.57075" xyz="-0.1 0.16 -0.1"/>
    <limit effort="100" velocity="100"/>  
    <joint_properties damping="0.0" friction="0.0"/>  
 </joint>  
  
 <link name="left_front_wheel">  
    <visual>  
      <geometry>  
        <cylinder length=".02" radius="0.1"/>
      </geometry>  
      <material name="black">  
        <color rgba="0 0 0 1"/>  
      </material>  
    </visual>  
  </link>  
  
  <joint name="left_front_wheel_joint" type="continuous">  
    <axis xyz="0 0 1"/>  
    <parent link="base_link"/>  
    <child link="left_front_wheel"/>  
    <origin rpy="0 1.57075 1.57075" xyz="0.25 -0.16 -0.05"/>
    <limit effort="100" velocity="100"/>  
    <joint_properties damping="0.0" friction="0.0"/>  
  </joint>  
  
  <link name="left_back_wheel">  
    <visual>  
      <geometry>  
        <cylinder length=".02" radius="0.055"/>
      </geometry>  
      <material name="black">  
        <color rgba="0 0 0 1"/>  
      </material>  
    </visual>  
  </link>  
  
  <joint name="left_back_wheel_joint" type="continuous">  
    <axis xyz="0 0 1"/>  
    <parent link="base_link"/>  
    <child link="left_back_wheel"/>  
    <origin rpy="0 1.57075 1.57075" xyz="-0.1 -0.16 -0.1"/>
    <limit effort="100" velocity="100"/>  
    <joint_properties damping="0.0" friction="0.0"/>  
  </joint>  
  
  <link name="laser">
    <visual>
      <geometry>  
        <box size=".02 .03 .03"/>  
      </geometry>  
      <material name="white">  
          <color rgba="1 1 1 1"/>  
      </material>  
    </visual>  
  </link>  
  
  <joint name="lidar" type="fixed">
    <parent link="base_link"/>  
    <child link="laser"/>
    <origin rpy="0 0 0" xyz="0.327 0 0.021"/> <!-- 1.57075 -->
  </joint>  

<link name="gyro">
    <visual>
      <geometry>  
        <box size=".02 .02 .03"/>  
      </geometry>  
      <material name="green">  
          <color rgba="0 1 0 1"/>  
      </material>  
    </visual>  
  </link>  
  
  <joint name="gyro" type="fixed">
    <parent link="base_link"/>  
    <child link="gyro"/>
    <origin rpy="0 0 0" xyz="-0.22 0 0.021"/> <!-- 1.57075 -->
  </joint>  
</robot>
